Workbook

Sheet READ ME
A1: Engine Ventures — New Deal Pipeline, ADVANCED-STAGE COHORT (rescoped 2026-09-02)
A3: Scope: every company appearing on a New Deal Meeting slide from 2025-10-14 through 2026-08-31 that reached Preliminary Diligence, Deep Diligence, Negotiate/Offer, or Legal Diligence at least once. Companies whose furthest stage was NewCo/Fellows, Hold/Nurture, or Meetings This Week were removed from this file on 2026-09-02, at the request of the deal team, to focus this database on companies past a first meeting. See the rescope log below for what was cut.
A4: 43 weekly meetings · 187 distinct companies in this file (was 481 pre-rescope, 498 pre-dedup) · built 2026-09-01, deduplicated & enriched 2026-09-02, rescoped to advanced-stage-only 2026-09-02.
A6: SOURCES AND PRECEDENCE
A7: 1. New Deal Meeting slides (PDF, 1,018 pages) — defines the population and ALL stage history.
A8: 2. Affinity export (581 records) — enrichment only. Never used to add a company.
A9: 3. Public sources — used only to fill gaps on advanced-stage companies; cited per row.
A11: Slides are the spine because Affinity is not a record of what was discussed: 103 of its
A12: 581 records were never contacted, and a January bulk import of 51 Swiss companies would
A13: distort any geographic analysis run off Affinity alone.
A15: HOW 'DISCUSSED' IS DEFINED
A16: discussed_in_new_deal_meeting = TRUE when the company name is BOLD on a meeting slide.
... A81: Data Dictionary — every field defined with its source.

Sheet Companies
A1: company_id | B1: company_name | C1: website | D1: discussed_in_new_deal_meeting | E1: discussion_dates | F1: first_discussion_date | G1: last_discussion_date | H1: times_discussed | I1: furthest_stage_on_slides | J1: date_reached_furthest_stage | K1: latest_stage_on_slides | L1: reached_prelim_diligence | M1: date_prelim_diligence | N1: reached_deep_diligence | O1: date_deep_diligence | P1: reached_negotiate_offer | Q1: date_negotiate_offer | R1: reached_legal | S1: date_legal | T1: slide_appearances | U1: first_slide_date | V1: last_slide_date | W1: working_group_final | X1: working_group_source | Y1: thesis_area_slides | Z1: stage | AA1: round_size_usd | AB1: hq_city | AC1: hq_state_province | AD1: hq_country | AE1: hq_region | AF1: affinity_status | AG1: interest | AH1: score_team | AI1: score_tech | AJ1: score_oppt | AK1: owner_name | AL1: owner_email | AM1: in_affinity | AN1: affinity_match_method | AO1: affinity_organization_id | AP1: affinity_row_id | AQ1: affinity_date_added | AR1: first_meeting | AS1: last_meeting | AT1: name_variants_on_slides | AU1: enriched_from_public | AV1: public_source | AW1: enrichment_priority | AX1: enrichment_gaps | AY1: needs_website | AZ1: needs_geography | BA1: needs_stage | BB1: needs_round_size | BC1: needs_owner | BD1: description
A2: EV0001 | B2: Bristol Superlight | C2: bristolsuperlight.com | D2: =TRUE() -> TRUE | E2: 2025-11-24; 2025-12-01; 2025-12-08; 2025-12-15; 2026-01-05; 2026-01-12; 2026-01-20; 2026-01-26; 2026-02-02; 2026-02-09; 2026-02-17; 2026-02-23; 2026-03-02; 2026-03-09; 2026-03-16; 2026-03-23; 2026-03-30; 2026-04-06; 2026-04-13; 2026-04-20; 2026-05-04; 2026-05-11; 2026-05-18 | F2: 45985 | G2: 46160 | H2: 23 | I2: Legal Diligence / Def Docs | J2: 46006 | K2: Legal Diligence / Def Docs | L2: =TRUE() -> TRUE | M2: 45957 | N2: =TRUE() -> TRUE | O2: 45985 | P2: =TRUE() -> TRUE | Q2: 45999 | R2: =TRUE() -> TRUE | S2: 46006 | T2: 27 | U2: 45957 | V2: 46160 | W2: Climate; Systems | X2: Affinity | Y2: Energy & Climate | Z2: Series A | AA2: 15000000 | AC2: England | AD2: United Kingdom | AE2: International | AF2: Invested | AG2: 1. Very High | AH2: '+++ | AI2: '+++ | AJ2: '++ | AK2: Rachel Field | AL2: rachel@engineventures.com | AM2: =TRUE() -> TRUE | AN2: name | AO2: 285295012 | AP2: 222880477 | AQ2: 10/22/2025 | AR2: 10/22/2025 | AS2: 08/14/2026 | AU2: =FALSE() -> FALSE | AW2: P4 - acceptable | AX2: 0 | AY2: =FALSE() -> FALSE | AZ2: =FALSE() -> FALSE | BA2: =FALSE() -> FALSE | BB2: =FALSE() -> FALSE | BC2: =FALSE() -> FALSE | BD2: Bristol Superlight is an automotive technology company based in Hampshire, United Kingdom, specializing in innovative logistics vehicle design. Their primary focus is developing plug-in hybrid trucks with advanced engineering features, including a lighter and stronger chassis constructed from composites and aluminum. The company employs a unique production system that enables efficient manufacturing of multiple vehicle variants, with a key emphasis on creating digital-first vehicles that reduce energy costs and optimize cargo transportation solutions for the modern logistics industry.
A3: EV0002 | B3: CorePower Magnetics | C3: corepowermagnetics.com | D3: =TRUE() -> TRUE | E3: 2025-10-14; 2025-10-20; 2025-10-27; 2025-11-03; 2025-11-10; 2026-01-26; 2026-03-09; 2026-03-16; 2026-03-23; 2026-05-04; 2026-05-11; 2026-05-18; 2026-05-26; 2026-06-01; 2026-06-08; 2026-06-15; 2026-06-22; 2026-07-06; 2026-07-13; 2026-07-20; 2026-07-27 | F3: 45944 | G3: 46230 | H3: 21 | I3: Legal Diligence / Def Docs | J3: 46153 | K3: Legal Diligence / Def Docs | L3: =TRUE() -> TRUE | M3: 46055 | N3: =TRUE() -> TRUE | O3: 45944 | P3: =TRUE() -> TRUE | Q3: 46146 | R3: =TRUE() -> TRUE | S3: 46153 | T3: 40 | U3: 45944 | V3: 46258 | W3: Climate | X3: Slide section | Y3: Energy & Climate | Z3: Series A | AB3: Pittsburgh | AC3: Pennsylvania | AD3: United States | AE3: United States | AM3: =FALSE() -> FALSE | AT3: Corepower Magnetics | AU3: 1 | AV3: Company site + CMU spinout announcement + PitchBook (founded 2020, CMU spinout); Scott Institute for Energy Innovation (CMU), Nov 2024: company was raising Series A funding, on top of a $2.5M pre-seed (2022) and non-dilutive DOE/ARPA-E grants. Current round size not confirmed in public sources. | AW3: P1 - advanced stage, incomplete | AX3: 2 | AY3: 0 | AZ3: 0 | BA3: 0 | BB3: 1 | BC3: 1
A4: EV0003 | B4: DG Matrix | C4: dgmatrix.com | D4: =TRUE() -> TRUE | E4: 2025-10-14; 2025-10-20; 2025-10-27; 2025-11-03; 2025-11-10; 2025-11-17; 2025-11-24; 2025-12-01; 2025-12-08; 2025-12-15; 2026-01-05; 2026-01-12; 2026-01-20; 2026-01-26; 2026-02-02; 2026-02-09; 2026-02-17 | F4: 45944 | G4: 46070 | H4: 17 | I4: Legal Diligence / Def Docs | J4: 45992 | K4: Legal Diligence / Def Docs | L4: =FALSE() -> FALSE | N4: =TRUE() -> TRUE | O4: 45944 | P4: =TRUE() -> TRUE | Q4: 45950 | R4: =TRUE() -> TRUE | S4: 45992 | T4: 17 | U4: 45944 | V4: 46070 | X4: MISSING | Z4: Series A | AA4: 60000000 | AB4: Morrisville | AC4: North Carolina | AD4: United States | AE4: United States | AK4: Michael Kearney | AM4: =FALSE() -> FALSE | AU4: 1 | AV4: BusinessWire 2026-02-18: $60M Series A led by Engine Ventures. NOTE: Crunchbase lists Raleigh, Tracxn lists Tempe - sources conflict, HQ per company press release; BusinessWire 2026-02-18 / Engine Ventures site: DG Matrix's $60M Series A (Feb 2026) was led by Engine Ventures, quoting Michael Kearney, General Partner -- likely deal owner, not confirmed against internal CRM. | AW4: P4 - acceptable | AX4: 0 | AY4: 0 | AZ4: 0 | BA4: 0 | BB4: 0 | BC4: 0
A5: EV0004 | B5: Alithia | C5: alithiapower.com | D5: =TRUE() -> TRUE | E5: 2026-05-11; 2026-05-26; 2026-06-01; 2026-06-08; 2026-06-15; 2026-06-22; 2026-07-06; 2026-07-13; 2026-07-20; 2026-07-27; 2026-08-24 | F5: 46153 | G5: 46258 | H5: 11 | I5: Deep Diligence | J5: 46168 | K5: Hold / Nurture | L5: =TRUE() -> TRUE | M5: 46146 | N5: =TRUE() -> TRUE | O5: 46168 | P5: =FALSE() -> FALSE | R5: =FALSE() -> FALSE | T5: 17 | U5: 46146 | V5: 46265 | W5: Systems | X5: Affinity | Y5: Autonomous Systems | Z5: Seed | AA5: 3000000 | AB5: Holly Springs | AC5: North Carolina | AD5: United States | AE5: United States | AF5: Deep Diligence | AG5: 1. Very High | AK5: Alaina Hartnett | AL5: alaina.hartnett@engineventures.com | AM5: =TRUE() -> TRUE | AN5: fuzzy | AO5: 292973343 | AP5: 238737706 | AQ5: 04/15/2026 | AR5: 04/15/2026 | AS5: 08/10/2026 | AU5: =TRUE() -> TRUE | AV5: Company site + ISES profile: Raleigh-Durham NC, founded Jan 2023, vertical GaN power electronics | AW5: P4 - acceptable | AX5: 0 | AY5: =FALSE() -> FALSE | AZ5: =FALSE() -> FALSE | BA5: =FALSE() -> FALSE | BB5: =FALSE() -> FALSE | BC5: =FALSE() -> FALSE | BD5: Alithia Power is a seed-stage technology company developing advanced vertical GaN (Gallium Nitride) power electronics for electrification markets. Founded in 2023 and based in Raleigh, NC, the company focuses on creating innovative power diodes and transistors with a compact design. Their vertiGAN™ technology aims to improve power system efficiency for electric vehicles, industrial motors, and renewable energy applications, emphasizing sustainable and high-performance power devices that can operate at high voltages with reduced reliance on traditional semiconductor chips.
A6: EV0005 | B6: Ovelle | C6: ovelle.bio | D6: =TRUE() -> TRUE | E6: 2026-02-23; 2026-03-09; 2026-03-16; 2026-03-23; 2026-03-30; 2026-04-06; 2026-04-13; 2026-04-20 | F6: 46076 | G6: 46132 | H6: 8 | I6: Legal Diligence / Def Docs | J6: 46111 | K6: Legal Diligence / Def Docs | L6: =TRUE() -> TRUE | M6: 45944 | N6: =TRUE() -> TRUE | O6: 46097 | P6: =TRUE() -> TRUE | Q6: 46104 | R6: =TRUE() -> TRUE | S6: 46111 | T6: 26 | U6: 45944 | V6: 46132 | W6: Health | X6: Affinity | Y6: Human Health | Z6: Seed | AA6: 10000000 | AB6: Boston | AC6: Massachusetts | AD6: United States | AE6: United States | AF6: Loss | AK6: Rachel Field | AL6: rachel@engineventures.com | AM6: =TRUE() -> TRUE | AN6: name | AO6: 300600234 | AP6: 218554332 | AQ6: 09/17/2025 | AR6: 09/17/2025 | AS6: 04/10/2026 | AU6: =FALSE() -> FALSE | AW6: P4 - acceptable | AX6: 0 | AY6: =FALSE() -> FALSE | AZ6: =FALSE() -> FALSE | BA6: =FALSE() -> FALSE | BB6: =FALSE() -> FALSE | BC6: =FALSE() -> FALSE | BD6: Ovelle is a pioneering biotechnology startup revolutionizing reproductive medicine through advanced in vitro gametogenesis (IVG) research. The company specializes in developing innovative fertility treatments by producing eggs from somatic cells using sophisticated computational methods and cellular manipulation techniques. Their groundbreaking approach aims to make fertility treatments more accessible, affordable, and less invasive by leveraging cutting-edge technologies like induced pluripotent stem cells and advanced genetic engineering.
A7: EV0006 | B7: Ayo Electronics | C7: ayoelectronics.com | D7: =TRUE() -> TRUE | E7: 2026-03-02; 2026-03-09; 2026-03-16; 2026-03-23; 2026-03-30; 2026-04-06 | F7: 46083 | G7: 46118 | H7: 6 | I7: Legal Diligence / Def Docs | J7: 46111 | K7: Legal Diligence / Def Docs | L7: =FALSE() -> FALSE | N7: =TRUE() -> TRUE | O7: 46083 | P7: =TRUE() -> TRUE | Q7: 46090 | R7: =TRUE() -> TRUE | S7: 46111 | T7: 6 | U7: 46083 | V7: 46118 | W7: Systems | X7: Affinity | Z7: Seed | AA7: 15000000 | AB7: Somerville | AC7: Massachusetts | AD7: United States | AE7: United States | AF7: Invested | AG7: 1. Very High | AK7: Madeleine Laitz | AL7: madeleine@engineventures.com | AM7: =TRUE() -> TRUE | AN7: domain | AO7: 290076693 | AP7: 234062557 | AQ7: 02/24/2026 | AR7: 12/06/2023 | AS7: 05/28/2026 | AU7: 1 | AV7: MassTech Northeast Microelectronics Coalition grant list (2025): Ayo Electronics Inc., Somerville, MA -- fabless semiconductor / photonic AI processor company (Pillar VC portfolio). PitchBook separately lists Arlington, MA; used the more specific, more recent source. | AW7: P4 - acceptable | AX7: 0 | AY7: 0 | AZ7: 0 | BA7: 0 | BB7: 0 | BC7: 0
A8: EV0007 | B8: Numem | C8: numem.com | D8: =TRUE() -> TRUE | E8: 2026-06-15; 2026-07-27; 2026-08-03; 2026-08-10; 2026-08-24; 2026-08-31 | F8: 46188 | G8: 46265 | H8: 6 | I8: Deep Diligence | J8: 46251 | K8: Deep Diligence | L8: =TRUE() -> TRUE | M8: 46153 | N8: =TRUE() -> TRUE | O8: 46251 | P8: =FALSE() -> FALSE | R8: =FALSE() -> FALSE | T8: 15 | U8: 46146 | V8: 46265 | W8: Systems | X8: Affinity | Y8: Autonomous Systems | Z8: Seed | AA8: 10000000 | AB8: Sunnyvale | AC8: California | AD8: United States | AE8: United States | AF8: Preliminary Diligence | AG8: 1. Very High | AK8: Alaina Hartnett | AL8: alaina.hartnett@engineventures.com | AM8: =TRUE() -> TRUE | AN8: name | AO8: 156979063 | AP8: 240451326 | AQ8: 05/06/2026 | AR8: 05/05/2026 | AS8: 08/21/2026 | AU8: =FALSE() -> FALSE | AW8: P4 - acceptable | AX8: 0 | AY8: =FALSE() -> FALSE | AZ8: =FALSE() -> FALSE | BA8: =FALSE() -> FALSE | BB8: =FALSE() -> FALSE | BC8: =FALSE() -> FALSE | BD8: Numem is a semiconductor technology company headquartered in Sunnyvale, California, specializing in advanced memory solutions based on patented NuRAM (MRAM) and SmartMem technologies. The company provides innovative SOC Subsystem IP Cores and Chiplets that offer a superior alternative to traditional SRAM and eFlash, delivering 2.5x smaller area and over 20x lower leakage power. Numem's solutions target critical technology sectors including IoT, wearables, AI/Generative AI, digital security, autonomous vehicles, and data centers, enabling customers to achieve substantial reductions in system power consumption and accelerated time to market.
A9: EV0008 | B9: Coral Innovations | C9: coral-innovations.com | D9: =TRUE() -> TRUE | E9: 2026-05-11; 2026-05-18; 2026-05-26; 2026-06-01; 2026-06-15 | F9: 46153 | G9: 46188 | H9: 5 | I9: Preliminary Diligence | J9: 46153 | K9: Preliminary Diligence | L9: =TRUE() -> TRUE | M9: 46153 | N9: =FALSE() -> FALSE | P9: =FALSE() -> FALSE | R9: =FALSE() -> FALSE | T9: 7 | U9: 46153 | V9: 46195 | W9: Climate | X9: Affinity | Y9: Energy & Climate | Z9: Seed | AA9: 4000000 | AB9: Evanston | AC9: Illinois | AD9: United States | AE9: United States | AF9: Pass | AG9: 2. High | AK9: Rachel Field | AL9: rachel@engineventures.com | AM9: =TRUE() -> TRUE | AN9: name | AO9: 301369744 | AP9: 240387693 | AQ9: 05/05/2026 | AR9: 05/05/2026 | AS9: 05/22/2026 | AU9: =FALSE() -> FALSE | AW9: P4 - acceptable | AX9: 0 | AY9: =FALSE() -> FALSE | AZ9: =FALSE() -> FALSE | BA9: =FALSE() -> FALSE | BB9: =FALSE() -> FALSE | BC9: =FALSE() -> FALSE | BD9: Coral Innovations is a nanotechnology company focused on developing sustainable environmental solutions, with a primary emphasis on water remediation and protection. Utilizing breakthrough research in nanotechnology, the company creates advanced solutions for clean water access, including portable water-quality testing units and specialized filtration materials. Their mission is to address environmental challenges by providing innovative, scalable technologies that help communities improve water quality, reduce environmental harm, and support long-term sustainability.
A10: EV0009 | B10: MatNex | C10: matnex.ai | D10: =TRUE() -> TRUE | E10: 2026-07-20; 2026-08-10; 2026-08-17; 2026-08-24; 2026-08-31 | F10: 46223 | G10: 46265 | H10: 5 | I10: Deep Diligence | J10: 46251 | K10: Deep Diligence | L10: =TRUE() -> TRUE | M10: 46216 | N10: =TRUE() -> TRUE | O10: 46251 | P10: =FALSE() -> FALSE | R10: =FALSE() -> FALSE | T10: 8 | U10: 46216 | V10: 46265 | W10: Climate; Systems | X10: Affinity | Y10: AI for Science | Z10: Series A | AA10: 20000000 | AB10: Cambridge | AC10: England | AD10: United Kingdom | AE10: International | AF10: Preliminary Diligence | AG10: 1. Very High | AK10: Alaina Hartnett | AL10: alaina.hartnett@engineventures.com | AM10: =TRUE() -> TRUE | AN10: name | AO10: 300461005 | AP10: 246051999 | AQ10: 07/08/2026 | AR10: 08/13/2026 | AS10: 08/13/2026 | AU10: =FALSE() -> FALSE | AW10: P4 - acceptable | AX10: 0 | AY10: =FALSE() -> FALSE | AZ10: =FALSE() -> FALSE | BA10: =FALSE() -> FALSE | BB10: =FALSE() -> FALSE | BC10: =FALSE() -> FALSE | BD10: Matnex is an AI-driven platform specializing in accelerating materials discovery and development with a focus on low-carbon solutions. Using advanced quantum calculations and automated processes, the company works with partners to dramatically reduce the time for discovering next-generation materials from decades to months. Their core mission is to discover new materials that can significantly reduce environmental, economic, and social costs, with a particular emphasis on lowering global CO2 emissions through innovative technological approaches.
A11: EV0010 | B11: Skouria | C11: skouria.com | D11: =TRUE() -> TRUE | E11: 2025-12-15; 2026-01-12; 2026-01-20; 2026-01-26; 2026-02-02 | F11: 46006 | G11: 46055 | H11: 5 | I11: Deep Diligence | J11: 46027 | K11: Deep Diligence | L11: =TRUE() -> TRUE | M11: 45964 | N11: =TRUE() -> TRUE | O11: 46027 | P11: =FALSE() -> FALSE | R11: =FALSE() -> FALSE | T11: 22 | U11: 45957 | V11: 46118 | W11: Climate | X11: Affinity | Y11: Energy & Climate | Z11: Seed | AA11: 7000000 | AB11: Philadelphia | AC11: Pennsylvania | AD11: United States | AE11: United States | AF11: Wait | AG11: 1. Very High | AH11: '++ | AI11: '+++ | AJ11: '+++ | AK11: Alaina Hartnett | AL11: alaina.hartnett@engineventures.com | AM11: =TRUE() -> TRUE | AN11: name | AO11: 296667487 | AP11: 223105565 | AQ11: 10/24/2025 | AR11: 10/28/2025 | AS11: 03/19/2026 | AU11: =FALSE() -> FALSE | AW11: P4 - acceptable | AX11: 0 | AY11: =FALSE() -> FALSE | AZ11: =FALSE() -> FALSE | BA11: =FALSE() -> FALSE | BB11: =FALSE() -> FALSE | BC11: =FALSE() -> FALSE | BD11: Skouria is a mining technology company specializing in innovative copper extraction through Deep Brine Mining (DBM), an advanced process designed to reduce environmental impact and capital costs. The company focuses on enhancing the permeability of hydrothermal systems using geothermal and metallurgical technologies to create a more sustainable copper production model. Their approach aims to optimize copper extraction while minimizing fossil fuel dependency and environmental disruption, offering consulting services to help governments and companies navigate complex copper industry challenges.
A12: EV0011 | B12: Teragen | C12: teragenenergy.com | D12: =TRUE() -> TRUE | E12: 2025-11-03; 2025-11-10; 2025-11-17; 2025-11-24; 2025-12-01 | F12: 45964 | G12: 45992 | H12: 5 | I12: Deep Diligence | J12: 45978 | K12: Meetings This Week | L12: =TRUE() -> TRUE | M12: 45944 | N12: =TRUE() -> TRUE | O12: 45978 | P12: =FALSE() -> FALSE | R12: =FALSE() -> FALSE | T12: 17 | U12: 45944 | V12: 46265 | W12: Climate | X12: Slide section | Y12: Energy & Climate | Z12: Preseed | AA12: 6000000 | AB12: Boston | AC12: Massachusetts | AD12: United States | AE12: United States | AM12: =FALSE() -> FALSE | AU12: 1 | AV12: Teragen Energy - Boston-based; $6M oversubscribed pre-seed (Aug 2026), co-led by BEVC and Energy Capital Ventures, participation incl. MassCEC. PR Newswire 2026-08-26. Spun out of Lawrence Berkeley National Lab per The Engine profile. Name match only -- not cross-checked against internal deal records; confirm before quoting externally. | AW12: P1 - advanced stage, incomplete | AX12: 1 | AY12: 0 | AZ12: 0 | BA12: 0 | BB12: 0 | BC12: 1
A13: EV0012 | B13: Axiomatic AI | C13: axiomatic-ai.com | D13: =TRUE() -> TRUE | E13: 2025-11-24; 2025-12-01; 2025-12-08; 2025-12-15 | F13: 45985 | G13: 46006 | H13: 4 | I13: Legal Diligence / Def Docs | J13: 46006 | K13: Meetings This Week | L13: =TRUE() -> TRUE | M13: 45971 | N13: =FALSE() -> FALSE | P13: =FALSE() -> FALSE | R13: =TRUE() -> TRUE | S13: 46006 | T13: 6 | U13: 45971 | V13: 46006 | W13: Systems | X13: Affinity | Y13: Autonomous Systems | Z13: Seed | AA13: 10000000 | AB13: Boston | AC13: Massachusetts | AD13: United States | AE13: United States | AF13: Invested | AG13: 1. Very High | AK13: Madeleine Laitz | AL13: madeleine@engineventures.com | AM13: =TRUE() -> TRUE | AN13: name | AO13: 294871569 | AP13: 224903165 | AQ13: 11/12/2025 | AR13: 05/15/2025 | AS13: 08/26/2026 | AU13: =FALSE() -> FALSE | AW13: P4 - acceptable | AX13: 0 | AY13: =FALSE() -> FALSE | AZ13: =FALSE() -> FALSE | BA13: =FALSE() -> FALSE | BB13: =FALSE() -> FALSE | BC13: =FALSE() -> FALSE | BD13: Axiomatic AI is an advanced artificial intelligence platform focused on accelerating research and development in science and engineering. The company aims to achieve Mission 10X30 by developing an AI-driven engineering tool that reduces technical challenge resolution time. Their unique approach combines formal verification with deep learning to create transparent, interpretable AI models for technical applications, particularly in photonics and semiconductor hardware development. The platform generates physics-based models, extracts technical documentation data, and provides automated design verification to minimize errors and improve technology development speed.
A14: EV0013 | B14: DINYA | C14: dinyadna.com | D14: =TRUE() -> TRUE | E14: 2025-10-14; 2025-10-27; 2025-11-03; 2025-11-10 | F14: 45944 | G14: 45971 | H14: 4 | I14: Deep Diligence | J14: 45957 | K14: Deep Diligence | L14: =TRUE() -> TRUE | M14: 45944 | N14: =TRUE() -> TRUE | O14: 45957 | P14: =FALSE() -> FALSE | R14: =FALSE() -> FALSE | T14: 5 | U14: 45944 | V14: 45971 | W14: Health | X14: Affinity | Y14: Human Health | Z14: Seed | AA14: 5000000 | AB14: Cambridge | AC14: Massachusetts | AD14: United States | AE14: United States | AF14: Pass | AK14: Deepa Rao | AL14: deepa@engineventures.com | AM14: =TRUE() -> TRUE | AN14: name | AO14: 293388830 | AP14: 218051781 | AQ14: 09/10/2025 | AR14: 11/20/2023 | AS14: 10/09/2025 | AU14: =FALSE() -> FALSE | AW14: P4 - acceptable | AX14: 0 | AY14: =FALSE() -> FALSE | AZ14: =FALSE() -> FALSE | BA14: =FALSE() -> FALSE | BB14: =FALSE() -> FALSE | BC14: =FALSE() -> FALSE | BD14: DINYA DNA is a biotechnology company specializing in enzymatic DNA synthesis, focusing on delivering complex and custom DNA sequences on-demand. The company enables scientific research by providing gene-length DNA quickly and affordably, supporting researchers in developing new scientific breakthroughs. Their technology allows for the creation of gene variant libraries and offers early access programs for potential research initiatives, ultimately accelerating research and development processes across various scientific fields.
A15: EV0014 | B15: Valor | D15: =TRUE() -> TRUE | E15: 2025-10-14; 2025-10-20; 2025-10-27; 2025-11-03 | F15: 45944 | G15: 45964 | H15: 4 | I15: Deep Diligence | J15: 45944 | K15: Deep Diligence | L15: =FALSE() -> FALSE | N15: =TRUE() -> TRUE | O15: 45944 | P15: =FALSE() -> FALSE | R15: =FALSE() -> FALSE | T15: 4 | U15: 45944 | V15: 45964 | W15: Climate | X15: Affinity | Z15: Seed | AA15: 10000000 | AE15: UNKNOWN | AF15: Loss | AG15: 1. Very High | AH15: '+++ | AI15: '+++ | AJ15: '+++ | AK15: Deepa Rao | AL15: deepa@engineventures.com | AM15: =TRUE() -> TRUE | AN15: name | AO15: 306041385 | AP15: 218669372 | AQ15: 09/17/2025 | AR15: 08/17/2023 | AS15: 04/03/2025 | AU15: =FALSE() -> FALSE | AW15: P1 - advanced stage, incomplete | AX15: 2 | AY15: =TRUE() -> TRUE | AZ15: =TRUE() -> TRUE | BA15: =FALSE() -> FALSE | BB15: =FALSE() -> FALSE | BC15: =FALSE() -> FALSE
A16: EV0015 | B16: Walden Robotics | C16: waldenrobotics.com | D16: =TRUE() -> TRUE | E16: 2026-05-11; 2026-05-18; 2026-05-26; 2026-06-01 | F16: 46153 | G16: 46174 | H16: 4 | I16: Preliminary Diligence | J16: 46146 | K16: Preliminary Diligence | L16: =TRUE() -> TRUE | M16: 46146 | N16: =FALSE() -> FALSE | P16: =FALSE() -> FALSE | R16: =FALSE() -> FALSE | T16: 5 | U16: 46146 | V16: 46174 | W16: Systems | X16: Affinity | Y16: Autonomous Systems | Z16: Series A | AA16: 250000000 | AB16: Cambridge | AC16: Massachusetts | AD16: United States | AE16: United States | AF16: Pass | AG16: 2. High | AK16: Rachel Field | AL16: rachel@engineventures.com | AM16: =TRUE() -> TRUE | AN16: name | AO16: 311096645 | AP16: 239805739 | AQ16: 04/28/2026 | AR16: 06/02/2026 | AS16: 06/02/2026 | AU16: =FALSE() -> FALSE | AW16: P4 - acceptable | AX16: 0 | AY16: =FALSE() -> FALSE | AZ16: =FALSE() -> FALSE | BA16: =FALSE() -> FALSE | BB16: =FALSE() -> FALSE | BC16: =FALSE() -> FALSE | BD16: we're a full-stack physical ai company building and deploying general-purpose robots that put human ingenuity to work at industrial scale. our robots continuously learn and improve while performing real work, today. and we are working toward a future where ai and robotics expand human potential and improve quality of life for everyone. founded in 2026 by pioneers in robotics and ai from toyota research institute, mit, stanford, and amazon, walden combines large behavior models with real-world operation and its own expert teams to bring capable robots to industry today.
A17: EV0016 | B17: Mattiq | C17: mattiq.com | D17: =TRUE() -> TRUE | E17: 2026-06-01; 2026-06-15; 2026-07-13 | F17: 46174 | G17: 46216 | H17: 3 | I17: Preliminary Diligence | J17: 46160 | K17: Preliminary Diligence | L17: =TRUE() -> TRUE | M17: 46160 | N17: =FALSE() -> FALSE | P17: =FALSE() -> FALSE | R17: =FALSE() -> FALSE | T17: 10 | U17: 46160 | V17: 46230 | W17: Systems | X17: Affinity | Y17: AI for Science | Z17: Seed | AA17: 10000000 | AB17: Chicago | AC17: Illinois | AD17: United States | AE17: United States | AF17: Preliminary Diligence | AG17: 5. Propose Pass | AK17: Alaina Hartnett | AL17: alaina.hartnett@engineventures.com | AM17: =TRUE() -> TRUE | AN17: name | AO17: 289307172 | AP17: 243153771 | AQ17: 06/12/2026 | AR17: 05/12/2026 | AS17: 08/03/2026 | AU17: =FALSE() -> FALSE | AW17: P4 - acceptable | AX17: 0 | AY17: =FALSE() -> FALSE | AZ17: =FALSE() -> FALSE | BA17: =FALSE() -> FALSE | BB17: =FALSE() -> FALSE | BC17: =FALSE() -> FALSE | BD17: Mattiq is an advanced clean chemistry company that leverages materials science and artificial intelligence to develop innovative electrochemical solutions for decarbonization. The company focuses on reinventing chemical process development to produce sustainable chemicals, fuels, and plastics. By utilizing AI and advanced technologies, Mattiq designs commercially viable, scalable processes that support supply chain resilience and environmental sustainability, with a particular emphasis on eliminating fossil fuel dependence in industrial chemical and energy sectors.
A18: EV0017 | B18: Attune Neurosci | C18: attuneneuro.com | D18: =TRUE() -> TRUE | E18: 2026-02-02; 2026-02-09 | F18: 46055 | G18: 46062 | H18: 2 | I18: Deep Diligence | J18: 46062 | K18: Deep Diligence | L18: =TRUE() -> TRUE | M18: 46006 | N18: =TRUE() -> TRUE | O18: 46062 | P18: =FALSE() -> FALSE | R18: =FALSE() -> FALSE | T18: 13 | U18: 45971 | V18: 46097 | W18: Health | X18: Affinity | Y18: Human Health | Z18: Series A | AA18: 20000000 | AB18: San Francisco | AC18: California | AD18: United States | AE18: United States | AF18: Pass | AK18: Rachel Field | AL18: rachel@engineventures.com | AM18: =TRUE() -> TRUE | AN18: fuzzy | AO18: 268186783 | AP18: 233316922 | AQ18: 02/12/2026 | AR18: 11/14/2025 | AS18: 03/27/2026 | AT18: Attune | AU18: 0 | AW18: P4 - acceptable | AX18: 0 | AY18: 0 | AZ18: 0 | BA18: 0 | BB18: 0 | BC18: 0 | BD18: Attune Neurosciences is a clinical-stage medical device company dedicated to improving human health and performance through non-invasive neurostimulation technologies. The company specializes in developing innovative neurological solutions, with a primary focus on low-intensity focused ultrasound targeting brain activity. Their research aims to enhance cognitive function and address conditions related to sleep, mental health, and overall performance. Attune Neurosciences develops clinically-proven products for patient, government, and industrial applications, seeking to provide cutting-edge neurological interventions without pharmaceutical approaches.
A19: EV0018 | B19: Cetos Water | C19: cetoswater.com | D19: =TRUE() -> TRUE | E19: 2026-05-26; 2026-06-01 | F19: 46168 | G19: 46174 | H19: 2 | I19: Preliminary Diligence | J19: 46062 | K19: Preliminary Diligence | L19: =TRUE() -> TRUE | M19: 46062 | N19: =FALSE() -> FALSE | P19: =FALSE() -> FALSE | R19: =FALSE() -> FALSE | T19: 19 | U19: 46055 | V19: 46265 | W19: Climate | X19: Affinity | Y19: Energy & Climate | Z19: Seed | AA19: 7000000 | AB19: New York | AC19: New York | AD19: United States | AE19: United States | AF19: Preliminary Diligence | AG19: 2. High | AK19: Alaina Hartnett | AL19: alaina.hartnett@engineventures.com | AM19: =TRUE() -> TRUE | AN19: name | AO19: 310756116 | AP19: 232338029 | AQ19: 02/03/2026 | AR19: 02/03/2026 | AS19: 08/05/2026 | AT19: Cetos Water / Kira; Water: Cetos Water / Kira | AU19: 0 | AW19: P4 - acceptable | AX19: 0 | AY19: 0 | AZ19: 0 | BA19: 0 | BB19: 0 | BC19: 0 | BD19: Cetos Water is an innovative water treatment technology company specializing in advanced desalination solutions for high-salinity wastewater streams. Their membrane-less and non-evaporative solvent technology can process water up to 10x more concentrated than seawater, enabling efficient treatment of complex industrial wastewater. The company serves multiple industries including lithium production, desalination plants, thermoelectric power, mining, and geothermal energy, with a mission to transform wastewater from an environmental challenge into a sustainable freshwater solution. Their technology supports customizable water recovery outcomes, including Zero Liquid Discharge (ZLD), addressing the critical issue of untreated wastewater discharge while providing cost-effective and energy-efficient water reclamation.
A20: EV0019 | B20: CloverLeaf | C20: cloverleafbio.com | D20: =TRUE() -> TRUE | E20: 2025-12-08; 2025-12-15 | F20: 45999 | G20: 46006 | H20: 2 | I20: Deep Diligence | J20: 46006 | K20: Deep Diligence | L20: =TRUE() -> TRUE | M20: 45978 | N20: =TRUE() -> TRUE | O20: 46006 | P20: =FALSE() -> FALSE | R20: =FALSE() -> FALSE | T20: 7 | U20: 45978 | V20: 46034 | W20: Health | X20: Affinity | Y20: Human Health | Z20: Seed | AA20: 12000000 | AB20: New Haven | AC20: Connecticut | AD20: United States | AE20: United States | AF20: Pass | AG20: 1. Very High | AK20: Dan Resnicow | AL20: dan@engineventures.com | AM20: =TRUE() -> TRUE | AN20: fuzzy | AO20: 291510341 | AP20: 230900570 | AQ20: 12/15/2025 | AR20: 10/30/2025 | AS20: 12/19/2025 | AU20: =FALSE() -> FALSE | AW20: P4 - acceptable | AX20: 0 | AY20: =FALSE() -> FALSE | AZ20: =FALSE() -> FALSE | BA20: =FALSE() -> FALSE | BB20: =FALSE() -> FALSE | BC20: =FALSE() -> FALSE | BD20: Cloverleaf Bio is a biotechnology company developing innovative RNA therapeutics focused on oncology treatment. The company is pioneering a platform that creates engineered RNA therapeutic molecules capable of targeting multiple enzymes critical to cancer growth. By developing a single therapeutic molecule that can inhibit up to 25 key enzymes, Cloverleaf aims to revolutionize cancer therapy and improve patient outcomes through advanced RNA therapeutic approaches.
A21: EV0020 | B21: 1AU | C21: 1autechnologies.com | D21: =TRUE() -> TRUE | E21: 2026-04-06 | F21: 46118 | G21: 46118 | H21: 1 | I21: Preliminary Diligence | J21: 46076 | K21: Preliminary Diligence | L21: =TRUE() -> TRUE | M21: 46076 | N21: =FALSE() -> FALSE | P21: =FALSE() -> FALSE | R21: =FALSE() -> FALSE | T21: 8 | U21: 46070 | V21: 46118 | W21: Systems | X21: Slide section | Y21: Autonomous Systems | AE21: UNKNOWN | AM21: =FALSE() -> FALSE | AU21: =FALSE() -> FALSE | AW21: P1 - discussed, incomplete | AX21: 5 | AY21: =TRUE() -> TRUE | AZ21: =TRUE() -> TRUE | BA21: =TRUE() -> TRUE | BB21: =TRUE() -> TRUE | BC21: =TRUE() -> TRUE
A22: EV0021 | B22: Blisk Dynamics | C22: bliskdynamics.com | D22: =TRUE() -> TRUE | E22: 2026-08-17 | F22: 46251 | G22: 46251 | H22: 1 | I22: Preliminary Diligence | J22: 46251 | K22: Preliminary Diligence | L22: =TRUE() -> TRUE | M22: 46251 | N22: =FALSE() -> FALSE | P22: =FALSE() -> FALSE | R22: =FALSE() -> FALSE | T22: 1 | U22: 46251 | V22: 46251 | W22: Systems; Climate | X22: Affinity | Y22: Autonomous Systems | Z22: Seed | AA22: 10000000 | AE22: UNKNOWN | AF22: Pass | AG22: 2. High | AK22: Rachel Field | AL22: rachel@engineventures.com | AM22: =TRUE() -> TRUE | AN22: name | AO22: 313497404 | AP22: 249444278 | AQ22: 08/12/2026 | AR22: 08/12/2026 | AS22: 08/18/2026 | AU22: =FALSE() -> FALSE | AW22: P1 - discussed, incomplete | AX22: 1 | AY22: =FALSE() -> FALSE | AZ22: =TRUE() -> TRUE | BA22: =FALSE() -> FALSE | BB22: =FALSE() -> FALSE | BC22: =FALSE() -> FALSE
A23: EV0022 | B23: Daedalus | C23: daedalus.de | D23: =TRUE() -> TRUE | E23: 2026-06-22 | F23: 46195 | G23: 46195 | H23: 1 | I23: Preliminary Diligence | J23: 46195 | K23: Preliminary Diligence | L23: =TRUE() -> TRUE | M23: 46195 | N23: =FALSE() -> FALSE | P23: =FALSE() -> FALSE | R23: =FALSE() -> FALSE | T23: 1 | U23: 46195 | V23: 46195 | W23: Systems | X23: Affinity | Y23: Autonomous Systems | Z23: Series B | AA23: 15000000 | AB23: San Francisco | AC23: California | AD23: United States | AE23: United States | AF23: Pass | AG23: 2. High | AK23: Vinny Beranek | AL23: vinny@engineventures.com | AM23: =TRUE() -> TRUE | AN23: name | AO23: 224087181 | AP23: 243429947 | AQ23: 06/17/2026 | AR23: 05/29/2026 | AS23: 06/10/2026 | AU23: =FALSE() -> FALSE | AW23: P4 - acceptable | AX23: 0 | AY23: =FALSE() -> FALSE | AZ23: =FALSE() -> FALSE | BA23: =FALSE() -> FALSE | BB23: =FALSE() -> FALSE | BC23: =FALSE() -> FALSE | BD23: Daedalus is an advanced manufacturing technology company developing software-defined, reconfigurable factories for precision component production. Backed by prominent venture capital firms including Khosla Ventures and Y Combinator, they leverage robotics and AI to enable agile manufacturing across various industries such as machinery, aerospace, semiconductor, and energy. Their approach emphasizes real-time production control, high-precision manufacturing, and the ability to rapidly retool for different part complexities, with a goal of creating more flexible, efficient, and sustainable industrial production capabilities.
A24: EV0023 | B24: El Agente | D24: =TRUE() -> TRUE | E24: 2026-02-02 | F24: 46055 | G24: 46055 | H24: 1 | I24: Preliminary Diligence | J24: 46055 | K24: Hold / Nurture | L24: =TRUE() -> TRUE | M24: 46055 | N24: =FALSE() -> FALSE | P24: =FALSE() -> FALSE | R24: =FALSE() -> FALSE | T24: 24 | U24: 46048 | V24: 46230 | W24: Systems | X24: Affinity | Y24: Autonomous Systems | Z24: Seed | AA24: 20000000 | AE24: UNKNOWN | AF24: Wait | AG24: 2. High | AH24: '+++ | AK24: Madeleine Laitz | AL24: madeleine@engineventures.com | AM24: =TRUE() -> TRUE | AN24: name | AO24: 310577715 | AP24: 231975755 | AQ24: 01/29/2026 | AU24: =FALSE() -> FALSE | AW24: P1 - discussed, incomplete | AX24: 2 | AY24: =TRUE() -> TRUE | AZ24: =TRUE() -> TRUE | BA24: =FALSE() -> FALSE | BB24: =FALSE() -> FALSE | BC24: =FALSE() -> FALSE
A25: EV0024 | B25: ExploreTech | C25: exploretech.ai | D25: =TRUE() -> TRUE | E25: 2026-07-27 | F25: 46230 | G25: 46230 | H25: 1 | I25: Preliminary Diligence | J25: 46209 | K25: Preliminary Diligence | L25: =TRUE() -> TRUE | M25: 46209 | N25: =FALSE() -> FALSE | P25: =FALSE() -> FALSE | R25: =FALSE() -> FALSE | T25: 8 | U25: 46209 | V25: 46258 | W25: Climate | X25: Affinity | Y25: Energy & Climate | Z25: Seed | AA25: 8000000 | AB25: San Diego | AC25: California | AD25: United States | AE25: United States | AF25: Preliminary Diligence | AG25: 3. Moderate | AK25: Alaina Hartnett | AL25: alaina.hartnett@engineventures.com | AM25: =TRUE() -> TRUE | AN25: name | AO25: 291146636 | AP25: 245020597 | AQ25: 06/26/2026 | AR25: 12/09/2025 | AS25: 07/10/2026 | AU25: =FALSE() -> FALSE | AW25: P4 - acceptable | AX25: 0 | AY25: =FALSE() -> FALSE | AZ25: =FALSE() -> FALSE | BA25: =FALSE() -> FALSE | BB25: =FALSE() -> FALSE | BC25: =FALSE() -> FALSE | BD25: ExploreTech is a technology company specializing in accelerating mineral exploration through advanced computational methods. Using a combination of geophysics, geology, and cutting-edge computing technologies, the company develops algorithms that dramatically speed up mineral discovery processes. Their innovative approach leverages real-time data streams, satellite imagery, and computational modeling to enhance exploration efficiency, providing integrated hardware and software solutions that can reduce exploration timelines from years to months.
A26: EV0025 | B26: Flume | C26: flumeinternet.com | D26: =TRUE() -> TRUE | E26: 2026-03-30 | F26: 46111 | G26: 46111 | H26: 1 | I26: Preliminary Diligence | J26: 46111 | K26: Preliminary Diligence | L26: =TRUE() -> TRUE | M26: 46111 | N26: =FALSE() -> FALSE | P26: =FALSE() -> FALSE | R26: =FALSE() -> FALSE | T26: 1 | U26: 46111 | V26: 46111 | W26: Systems | X26: Affinity | Y26: Autonomous Systems | Z26: Series A | AA26: 15000000 | AB26: New York | AC26: New York | AD26: United States | AE26: United States | AF26: Pass | AG26: 1. Very High | AK26: Madeleine Laitz | AL26: madeleine@engineventures.com | AM26: =TRUE() -> TRUE | AN26: name | AO26: 263318060 | AP26: 237720127 | AQ26: 04/01/2026 | AR26: 06/13/2018 | AS26: 04/03/2026 | AU26: =FALSE() -> FALSE | AW26: P4 - acceptable | AX26: 0 | AY26: =FALSE() -> FALSE | AZ26: =FALSE() -> FALSE | BA26: =FALSE() -> FALSE | BB26: =FALSE() -> FALSE | BC26: =FALSE() -> FALSE | BD26: Flume is an asset-light fiber internet service provider focused on expanding broadband connectivity across the United States. The company specializes in providing multi-gigabit internet services to residential multifamily properties and small municipalities, leveraging under-utilized data centers and fiber infrastructure. With internet speeds ranging from 200 Mb/s to 10 Gb/s, Flume offers reliable connectivity, free installation, and proactive customer support. The company has rapidly grown its install base and aims to serve over 65,000 homes, targeting both residential and enterprise customers with a lean operational approach.
A27: EV0027 | B27: Human Bio | C27: humanbio.tech | D27: =TRUE() -> TRUE | E27: 2026-01-26 | F27: 46048 | G27: 46048 | H27: 1 | I27: Preliminary Diligence | J27: 46042 | K27: Preliminary Diligence | L27: =TRUE() -> TRUE | M27: 46042 | N27: =FALSE() -> FALSE | P27: =FALSE() -> FALSE | R27: =FALSE() -> FALSE | T27: 3 | U27: 46042 | V27: 46055 | W27: Health | X27: Affinity | Y27: Human Health | Z27: Preseed | AA27: 12000000 | AE27: UNKNOWN | AF27: Pass | AK27: Vinny Beranek | AL27: vinny@engineventures.com | AM27: =TRUE() -> TRUE | AN27: name | AO27: 310154725 | AP27: 231875973 | AQ27: 01/28/2026 | AR27: 01/16/2026 | AS27: 02/05/2026 | AU27: =FALSE() -> FALSE | AW27: P1 - discussed, incomplete | AX27: 1 | AY27: =FALSE() -> FALSE | AZ27: =TRUE() -> TRUE | BA27: =FALSE() -> FALSE | BB27: =FALSE() -> FALSE | BC27: =FALSE() -> FALSE | BD27: Developing new drugs for approved targets in novel, de-risked lead indications (“first-in-indication”), guided by human real-world data and genetics
A28: EV0028 | B28: Lila Sciences | C28: lila.ai | D28: =TRUE() -> TRUE | E28: 2026-03-02 | F28: 46083 | G28: 46083 | H28: 1 | I28: Deep Diligence | J28: 46083 | K28: Deep Diligence | L28: =TRUE() -> TRUE | M28: 45957 | N28: =TRUE() -> TRUE | O28: 46083 | P28: =FALSE() -> FALSE | R28: =FALSE() -> FALSE | T28: 4 | U28: 45957 | V28: 46083 | W28: Health | X28: Slide section | Y28: Human Health | Z28: Series B | AA28: 2000000000 | AB28: Cambridge | AC28: Massachusetts | AD28: United States | AE28: United States | AM28: =FALSE() -> FALSE | AU28: 1 | AV28: PitchBook / FinSMEs 2026-06: Cambridge MA, $550M raised to date; Bloomberg 2026-06-03: reported in talks for ~$2B Series B at ~$8.5B pre-money valuation (NOT confirmed closed as of last public reporting); prior $350M Series A closed 2026-06-04 (FinSMEs). | AW28: P1 - advanced stage, incomplete | AX28: 1 | AY28: 0 | AZ28: 0 | BA28: 0 | BB28: 0 | BC28: 1
A29: EV0029 | B29: Micrographia Bio | C29: micrographiabio.com | D29: =TRUE() -> TRUE | E29: 2025-11-03 | F29: 45964 | G29: 45964 | H29: 1 | I29: Preliminary Diligence | J29: 45957 | K29: Preliminary Diligence | L29: =TRUE() -> TRUE | M29: 45957 | N29: =FALSE() -> FALSE | P29: =FALSE() -> FALSE | R29: =FALSE() -> FALSE | T29: 8 | U29: 45957 | V29: 46006 | W29: Systems | X29: Affinity | Y29: Human Health | Z29: Seed | AB29: London | AC29: England | AD29: United Kingdom | AE29: International | AF29: Initial Evaluation | AM29: =TRUE() -> TRUE | AN29: name | AO29: 262788047 | AP29: 230015200 | AQ29: 01/08/2026 | AR29: 10/22/2025 | AS29: 11/13/2025 | AU29: 1 | AV29: Tracxn / PitchBook / Dealroom (2026): Seed-stage financing history, ~$7.8-8.0M total raised across 3 seed rounds since 2020; no Series A reported. London, UK confirmed (already on file). | AW29: P1 - discussed, incomplete | AX29: 2 | AY29: 0 | AZ29: 0 | BA29: 0 | BB29: 1 | BC29: 1 | BD29: Micrographia Bio is a life sciences company pioneering innovative drug discovery technologies through spatial proteomics. The company has developed a unique platform that combines advanced microscopy imaging with machine-intelligent computer vision to autonomously assess therapeutic mechanisms of action. By visualizing protein-protein networks in cells, their technology aims to accelerate and improve the efficiency of drug development, providing detailed insights into cellular pathways and potentially enabling faster, more accurate therapies for various diseases.
A30: EV0030 | B30: Origins AI | D30: =TRUE() -> TRUE | E30: 2026-08-03 | F30: 46237 | G30: 46237 | H30: 1 | I30: Preliminary Diligence | J30: 46237 | K30: Preliminary Diligence | L30: =TRUE() -> TRUE | M30: 46237 | N30: =FALSE() -> FALSE | P30: =FALSE() -> FALSE | R30: =FALSE() -> FALSE | T30: 1 | U30: 46237 | V30: 46237 | W30: Systems | X30: Affinity | Y30: AI for Science | Z30: Seed | AA30: 15000000 | AE30: UNKNOWN | AF30: Preliminary Diligence | AG30: 4. Low | AK30: Richard Collins | AL30: richard@engineventures.com | AM30: =TRUE() -> TRUE | AN30: name | AO30: 313514967 | AP30: 248367014 | AQ30: 07/31/2026 | AU30: =FALSE() -> FALSE | AW30: P1 - discussed, incomplete | AX30: 2 | AY30: =TRUE() -> TRUE | AZ30: =TRUE() -> TRUE | BA30: =FALSE() -> FALSE | BB30: =FALSE() -> FALSE | BC30: =FALSE() -> FALSE
A31: EV0031 | B31: Oxipital AI | C31: oxipitalai.com | D31: =TRUE() -> TRUE | E31: 2026-04-06 | F31: 46118 | G31: 46118 | H31: 1 | I31: Preliminary Diligence | J31: 46118 | K31: Preliminary Diligence | L31: =TRUE() -> TRUE | M31: 46118 | N31: =FALSE() -> FALSE | P31: =FALSE() -> FALSE | R31: =FALSE() -> FALSE | T31: 1 | U31: 46118 | V31: 46118 | W31: Systems | X31: Affinity | Y31: Autonomous Systems | Z31: Series A | AA31: 6000000 | AB31: Bedford | AC31: Massachusetts | AD31: United States | AE31: United States | AF31: Pass | AG31: 3. Moderate | AK31: Madeleine Laitz | AL31: madeleine@engineventures.com | AM31: =TRUE() -> TRUE | AN31: domain | AO31: 297882448 | AP31: 237790190 | AQ31: 04/02/2026 | AR31: 04/07/2020 | AS31: 03/31/2026 | AU31: =FALSE() -> FALSE | AW31: P4 - acceptable | AX31: 0 | AY31: =FALSE() -> FALSE | AZ31: =FALSE() -> FALSE | BA31: =FALSE() -> FALSE | BB31: =FALSE() -> FALSE | BC31: =FALSE() -> FALSE | BD31: Oxipital AI is a technology company specializing in AI-enabled machine vision solutions for robotic process automation and product inspection across critical industries including food processing, agriculture, and consumer goods production. Their platform delivers advanced visual AI technologies that enable no-code deployment of intelligent inspection systems, allowing manufacturers to automate quality control processes, monitor product characteristics in real-time, and perform automated pick and place inspections. The company focuses on enhancing manufacturing efficiency, sustainability, and operational resilience by providing actionable insights through deep object understanding and advanced visual technology.
A32: EV0032 | B32: PHNX Materials | C32: phnxmaterials.com | D32: =TRUE() -> TRUE | E32: 2025-10-27 | F32: 45957 | G32: 45957 | H32: 1 | I32: Preliminary Diligence | J32: 45944 | K32: Preliminary Diligence | L32: =TRUE() -> TRUE | M32: 45944 | N32: =FALSE() -> FALSE | P32: =FALSE() -> FALSE | R32: =FALSE() -> FALSE | T32: 4 | U32: 45944 | V32: 45964 | W32: Climate | X32: Affinity | Y32: Energy & Climate | Z32: Seed | AA32: 6000000 | AB32: San Francisco | AC32: California | AD32: United States | AE32: United States | AF32: Wait | AG32: 2. High | AK32: Deepa Rao | AL32: deepa@engineventures.com | AM32: =TRUE() -> TRUE | AN32: name | AO32: 300391587 | AP32: 220885034 | AQ32: 10/08/2025 | AR32: 10/08/2025 | AS32: 10/29/2025 | AU32: =FALSE() -> FALSE | AW32: P4 - acceptable | AX32: 0 | AY32: =FALSE() -> FALSE | AZ32: =FALSE() -> FALSE | BA32: =FALSE() -> FALSE | BB32: =FALSE() -> FALSE | BC32: =FALSE() -> FALSE | BD32: PHNX Materials is an industrial technology company that transforms landfilled coal ash into sustainable, high-performance materials using proprietary chemistry-driven processes. The company addresses the 2.9 billion tons of coal ash waste in U.S. landfills by reclaiming, refining, and reinventing it into valuable industrial inputs including ASTM-grade fly ash for concrete strengthening, strategic metals like aluminum and rare earth elements, and critical chemical compounds for domestic manufacturing. PHNX Materials' validated, scalable technology reduces carbon emissions, supports infrastructure rebuilding, and reshores critical supply chains while converting waste into essential materials for a cleaner, more resilient industrial base.
A33: EV0033 | B33: Prahelika | C33: prahelika.com | D33: =TRUE() -> TRUE | E33: 2026-08-24 | F33: 46258 | G33: 46258 | H33: 1 | I33: Preliminary Diligence | J33: 46237 | K33: Preliminary Diligence | L33: =TRUE() -> TRUE | M33: 46237 | N33: =FALSE() -> FALSE | P33: =FALSE() -> FALSE | R33: =FALSE() -> FALSE | T33: 4 | U33: 46237 | V33: 46258 | W33: Systems | X33: Affinity | Y33: Autonomous Systems | Z33: Seed | AA33: 17000000 | AE33: UNKNOWN | AF33: Preliminary Diligence | AG33: 1. Very High | AK33: Alaina Hartnett | AL33: alaina.hartnett@engineventures.com | AM33: =TRUE() -> TRUE | AN33: name | AO33: 311400320 | AP33: 250054857 | AQ33: 08/19/2026 | AR33: 04/01/2026 | AS33: 08/21/2026 | AU33: =FALSE() -> FALSE | AW33: P1 - discussed, incomplete | AX33: 1 | AY33: =FALSE() -> FALSE | AZ33: =TRUE() -> TRUE | BA33: =FALSE() -> FALSE | BB33: =FALSE() -> FALSE | BC33: =FALSE() -> FALSE
A34: EV0034 | B34: ScaleLight / TopoLight | D34: =TRUE() -> TRUE | E34: 2026-04-06 | F34: 46118 | G34: 46118 | H34: 1 | I34: Preliminary Diligence | J34: 46118 | K34: Preliminary Diligence | L34: =TRUE() -> TRUE | M34: 46118 | N34: =FALSE() -> FALSE | P34: =FALSE() -> FALSE | R34: =FALSE() -> FALSE | T34: 1 | U34: 46118 | V34: 46118 | W34: Systems | X34: Affinity | Y34: Autonomous Systems | Z34: Seed | AA34: 10000000 | AE34: UNKNOWN | AF34: Wait | AG34: 2. High | AK34: Madeleine Laitz | AL34: madeleine@engineventures.com | AM34: =TRUE() -> TRUE | AN34: fuzzy | AO34: 311517728 | AP34: 237197317 | AQ34: 03/26/2026 | AU34: =FALSE() -> FALSE | AW34: P1 - discussed, incomplete | AX34: 2 | AY34: =TRUE() -> TRUE | AZ34: =TRUE() -> TRUE | BA34: =FALSE() -> FALSE | BB34: =FALSE() -> FALSE | BC34: =FALSE() -> FALSE
A35: EV0035 | B35: /Eden Tech | C35: edentechinc.com | D35: =FALSE() -> FALSE | H35: 0 | I35: Preliminary Diligence | J35: 46070 | K35: Preliminary Diligence | L35: =TRUE() -> TRUE | M35: 46070 | N35: =FALSE() -> FALSE | P35: =FALSE() -> FALSE | R35: =FALSE() -> FALSE | T35: 1 | U35: 46070 | V35: 46070 | W35: Climate | X35: Affinity | Y35: Energy & Climate | AB35: Lockhart | AC35: Texas | AD35: United States | AE35: United States | AF35: Pre-Screen | AK35: Alaina Hartnett | AL35: alaina.hartnett@engineventures.com | AM35: =TRUE() -> TRUE | AN35: fuzzy | AO35: 278244151 | AP35: 233706001 | AQ35: 02/18/2026 | AR35: 02/10/2026 | AS35: 02/10/2026 | AU35: =FALSE() -> FALSE | AW35: P4 - acceptable | AX35: 2 | AY35: =FALSE() -> FALSE | AZ35: =FALSE() -> FALSE | BA35: =TRUE() -> TRUE | BB35: =TRUE() -> TRUE | BC35: =FALSE() -> FALSE | BD35: Eden Technologies is an innovative water technology company specializing in advanced desalination solutions. Their core product is a novel Reverse-Osmosis (RO) Centrifuge that uses centrifugal force to process brackish and saline water more efficiently. The technology aims to expand clean water access globally by increasing freshwater recovery rates up to 40% and reducing membrane fouling in desalination plants. Their approach focuses on developing cost-effective and environmentally safe water treatment technologies that improve the performance and profitability of water treatment facilities.
A36: EV0042 | B36: Adiabatic Machines | C36: adiabaticmachines.com | D36: =FALSE() -> FALSE | H36: 0 | I36: Preliminary Diligence | J36: 46230 | K36: Preliminary Diligence | L36: =TRUE() -> TRUE | M36: 46230 | N36: =FALSE() -> FALSE | P36: =FALSE() -> FALSE | R36: =FALSE() -> FALSE | T36: 18 | U36: 45978 | V36: 46265 | W36: Systems | X36: Affinity | Y36: Autonomous Systems | Z36: Preseed | AA36: 6000000 | AE36: UNKNOWN | AF36: Preliminary Diligence | AG36: 2. High | AH36: '++ | AI36: '+++ | AJ36: '+++ | AK36: Deepa Rao | AL36: deepa@engineventures.com | AM36: =TRUE() -> TRUE | AN36: name | AO36: 313217896 | AP36: 246954853 | AQ36: 07/14/2026 | AR36: 07/21/2026 | AS36: 08/11/2026 | AT36: Adiabatic machines; Machines | AU36: 0 | AW36: P4 - acceptable | AX36: 1 | AY36: 0 | AZ36: 1 | BA36: 0 | BB36: 0 | BC36: 0
A37: EV0044 | B37: Aepnus | C37: aepnus.com | D37: =FALSE() -> FALSE | H37: 0 | I37: Preliminary Diligence | J37: 45944 | K37: Preliminary Diligence | L37: =TRUE() -> TRUE | M37: 45944 | N37: =FALSE() -> FALSE | P37: =FALSE() -> FALSE | R37: =FALSE() -> FALSE | T37: 10 | U37: 45944 | V37: 46042 | W37: Climate | X37: Slide section | Y37: Energy & Climate | AE37: UNKNOWN | AM37: =FALSE() -> FALSE | AU37: =FALSE() -> FALSE | AW37: P2 - prelim dil, mostly empty | AX37: 5 | AY37: =TRUE() -> TRUE | AZ37: =TRUE() -> TRUE | BA37: =TRUE() -> TRUE | BB37: =TRUE() -> TRUE | BC37: =TRUE() -> TRUE
A38: EV0045 | B38: Aeris | D38: =FALSE() -> FALSE | H38: 0 | I38: Preliminary Diligence | J38: 45944 | K38: Preliminary Diligence | L38: =TRUE() -> TRUE | M38: 45944 | N38: =FALSE() -> FALSE | P38: =FALSE() -> FALSE | R38: =FALSE() -> FALSE | T38: 4 | U38: 45944 | V38: 45964 | W38: Systems | X38: Slide section | Y38: Autonomous Systems | AE38: UNKNOWN | AM38: =FALSE() -> FALSE | AU38: =FALSE() -> FALSE | AW38: P2 - prelim dil, mostly empty | AX38: 5 | AY38: =TRUE() -> TRUE | AZ38: =TRUE() -> TRUE | BA38: =TRUE() -> TRUE | BB38: =TRUE() -> TRUE | BC38: =TRUE() -> TRUE
A39: EV0048 | B39: Aikido Technologies | C39: aikidotechnologies.com | D39: =FALSE() -> FALSE | H39: 0 | I39: Preliminary Diligence | J39: 46223 | K39: Preliminary Diligence | L39: =TRUE() -> TRUE | M39: 46223 | N39: =FALSE() -> FALSE | P39: =FALSE() -> FALSE | R39: =FALSE() -> FALSE | T39: 7 | U39: 46216 | V39: 46258 | W39: Climate | X39: Affinity | Y39: Energy & Climate | Z39: Seed | AA39: 5000000 | AB39: San Francisco | AC39: California | AD39: United States | AE39: United States | AF39: Preliminary Diligence | AG39: 2. High | AK39: Deepa Rao | AL39: deepa@engineventures.com | AM39: =TRUE() -> TRUE | AN39: name | AO39: 287770819 | AP39: 247086373 | AQ39: 07/16/2026 | AR39: 07/13/2026 | AS39: 07/28/2026 | AU39: =FALSE() -> FALSE | AW39: P4 - acceptable | AX39: 0 | AY39: =FALSE() -> FALSE | AZ39: =FALSE() -> FALSE | BA39: =FALSE() -> FALSE | BB39: =FALSE() -> FALSE | BC39: =FALSE() -> FALSE | BD39: Aikido Technologies is an innovative renewable energy company specializing in floating offshore wind platform technology. The company develops solutions for deploying wind turbines in deep water, enabling energy providers to cost-effectively install large turbines with minimal construction time and labor. Their technology is designed to unlock local maritime infrastructure, create high-paying jobs in coastal communities, and provide low-cost, clean electricity to urban areas. By offering a versatile platform that supports efficient wind energy deployment, Aikido Technologies aims to advance sustainable energy production and support local economic development.
A40: EV0052 | B40: Alkali Labs | C40: alkalilabs.com | D40: =FALSE() -> FALSE | H40: 0 | I40: Preliminary Diligence | J40: 45944 | K40: Preliminary Diligence | L40: =TRUE() -> TRUE | M40: 45944 | N40: =FALSE() -> FALSE | P40: =FALSE() -> FALSE | R40: =FALSE() -> FALSE | T40: 2 | U40: 45944 | V40: 45950 | W40: Climate | X40: Slide section | Y40: Energy & Climate | AE40: UNKNOWN | AM40: =FALSE() -> FALSE | AU40: =FALSE() -> FALSE | AW40: P2 - prelim dil, mostly empty | AX40: 5 | AY40: =TRUE() -> TRUE | AZ40: =TRUE() -> TRUE | BA40: =TRUE() -> TRUE | BB40: =TRUE() -> TRUE | BC40: =TRUE() -> TRUE
...

Sheet Discussed Companies
A1: company_id | B1: company_name | C1: times_discussed | D1: first_discussion_date | E1: last_discussion_date | F1: discussion_dates | G1: furthest_stage_on_slides | H1: date_deep_diligence | I1: date_legal | J1: stage | K1: round_size_usd | L1: working_group_final | M1: hq_city | N1: hq_state_province | O1: hq_country | P1: affinity_status | Q1: owner_name
A2: EV0001 | B2: Bristol Superlight | C2: 23 | D2: 45985 | E2: 46160 | F2: 2025-11-24; 2025-12-01; 2025-12-08; 2025-12-15; 2026-01-05; 2026-01-12; 2026-01-20; 2026-01-26; 2026-02-02; 2026-02-09; 2026-02-17; 2026-02-23; 2026-03-02; 2026-03-09; 2026-03-16; 2026-03-23; 2026-03-30; 2026-04-06; 2026-04-13; 2026-04-20; 2026-05-04; 2026-05-11; 2026-05-18 | G2: Legal Diligence / Def Docs | H2: 45985 | I2: 46006 | J2: Series A | K2: 15000000 | L2: Climate; Systems | N2: England | O2: United Kingdom | P2: Invested | Q2: Rachel Field
A3: EV0002 | B3: CorePower Magnetics | C3: 21 | D3: 45944 | E3: 46230 | F3: 2025-10-14; 2025-10-20; 2025-10-27; 2025-11-03; 2025-11-10; 2026-01-26; 2026-03-09; 2026-03-16; 2026-03-23; 2026-05-04; 2026-05-11; 2026-05-18; 2026-05-26; 2026-06-01; 2026-06-08; 2026-06-15; 2026-06-22; 2026-07-06; 2026-07-13; 2026-07-20; 2026-07-27 | G3: Legal Diligence / Def Docs | H3: 45944 | I3: 46153 | L3: Climate | M3: Pittsburgh | N3: Pennsylvania | O3: United States
A4: EV0003 | B4: DG Matrix | C4: 17 | D4: 45944 | E4: 46070 | F4: 2025-10-14; 2025-10-20; 2025-10-27; 2025-11-03; 2025-11-10; 2025-11-17; 2025-11-24; 2025-12-01; 2025-12-08; 2025-12-15; 2026-01-05; 2026-01-12; 2026-01-20; 2026-01-26; 2026-02-02; 2026-02-09; 2026-02-17 | G4: Legal Diligence / Def Docs | H4: 45944 | I4: 45992 | J4: Series A | K4: 60000000 | M4: Morrisville | N4: North Carolina | O4: United States
A5: EV0004 | B5: Alithia | C5: 11 | D5: 46153 | E5: 46258 | F5: 2026-05-11; 2026-05-26; 2026-06-01; 2026-06-08; 2026-06-15; 2026-06-22; 2026-07-06; 2026-07-13; 2026-07-20; 2026-07-27; 2026-08-24 | G5: Deep Diligence | H5: 46168 | J5: Seed | K5: 3000000 | L5: Systems | M5: Holly Springs | N5: North Carolina | O5: United States | P5: Deep Diligence | Q5: Alaina Hartnett
A6: EV0005 | B6: Ovelle | C6: 8 | D6: 46076 | E6: 46132 | F6: 2026-02-23; 2026-03-09; 2026-03-16; 2026-03-23; 2026-03-30; 2026-04-06; 2026-04-13; 2026-04-20 | G6: Legal Diligence / Def Docs | H6: 46097 | I6: 46111 | J6: Seed | K6: 10000000 | L6: Health | M6: Boston | N6: Massachusetts | O6: United States | P6: Loss | Q6: Rachel Field
A7: EV0006 | B7: Ayo Electronics | C7: 6 | D7: 46083 | E7: 46118 | F7: 2026-03-02; 2026-03-09; 2026-03-16; 2026-03-23; 2026-03-30; 2026-04-06 | G7: Legal Diligence / Def Docs | H7: 46083 | I7: 46111 | J7: Seed | K7: 15000000 | L7: Systems | P7: Invested | Q7: Madeleine Laitz
A8: EV0007 | B8: Numem | C8: 6 | D8: 46188 | E8: 46265 | F8: 2026-06-15; 2026-07-27; 2026-08-03; 2026-08-10; 2026-08-24; 2026-08-31 | G8: Deep Diligence | H8: 46251 | J8: Seed | K8: 10000000 | L8: Systems | M8: Sunnyvale | N8: California | O8: United States | P8: Preliminary Diligence | Q8: Alaina Hartnett
A9: EV0008 | B9: Coral Innovations | C9: 5 | D9: 46153 | E9: 46188 | F9: 2026-05-11; 2026-05-18; 2026-05-26; 2026-06-01; 2026-06-15 | G9: Preliminary Diligence | J9: Seed | K9: 4000000 | L9: Climate | M9: Evanston | N9: Illinois | O9: United States | P9: Pass | Q9: Rachel Field
A10: EV0009 | B10: MatNex | C10: 5 | D10: 46223 | E10: 46265 | F10: 2026-07-20; 2026-08-10; 2026-08-17; 2026-08-24; 2026-08-31 | G10: Deep Diligence | H10: 46251 | J10: Series A | K10: 20000000 | L10: Climate; Systems | M10: Cambridge | N10: England | O10: United Kingdom | P10: Preliminary Diligence | Q10: Alaina Hartnett
A11: EV0010 | B11: Skouria | C11: 5 | D11: 46006 | E11: 46055 | F11: 2025-12-15; 2026-01-12; 2026-01-20; 2026-01-26; 2026-02-02 | G11: Deep Diligence | H11: 46027 | J11: Seed | K11: 7000000 | L11: Climate | M11: Philadelphia | N11: Pennsylvania | O11: United States | P11: Wait | Q11: Alaina Hartnett
A12: EV0011 | B12: Teragen | C12: 5 | D12: 45964 | E12: 45992 | F12: 2025-11-03; 2025-11-10; 2025-11-17; 2025-11-24; 2025-12-01 | G12: Deep Diligence | H12: 45978 | L12: Climate
A13: EV0012 | B13: Axiomatic AI | C13: 4 | D13: 45985 | E13: 46006 | F13: 2025-11-24; 2025-12-01; 2025-12-08; 2025-12-15 | G13: Legal Diligence / Def Docs | I13: 46006 | J13: Seed | K13: 10000000 | L13: Systems | M13: Boston | N13: Massachusetts | O13: United States | P13: Invested | Q13: Madeleine Laitz
A14: EV0013 | B14: DINYA | C14: 4 | D14: 45944 | E14: 45971 | F14: 2025-10-14; 2025-10-27; 2025-11-03; 2025-11-10 | G14: Deep Diligence | H14: 45957 | J14: Seed | K14: 5000000 | L14: Health | M14: Cambridge | N14: Massachusetts | O14: United States | P14: Pass | Q14: Deepa Rao
A15: EV0014 | B15: Valor | C15: 4 | D15: 45944 | E15: 45964 | F15: 2025-10-14; 2025-10-20; 2025-10-27; 2025-11-03 | G15: Deep Diligence | H15: 45944 | J15: Seed | K15: 10000000 | L15: Climate | P15: Loss | Q15: Deepa Rao
A16: EV0015 | B16: Walden Robotics | C16: 4 | D16: 46153 | E16: 46174 | F16: 2026-05-11; 2026-05-18; 2026-05-26; 2026-06-01 | G16: Preliminary Diligence | J16: Series A | K16: 250000000 | L16: Systems | M16: Cambridge | N16: Massachusetts | O16: United States | P16: Pass | Q16: Rachel Field
A17: EV0016 | B17: Mattiq | C17: 3 | D17: 46174 | E17: 46216 | F17: 2026-06-01; 2026-06-15; 2026-07-13 | G17: Preliminary Diligence | J17: Seed | K17: 10000000 | L17: Systems | M17: Chicago | N17: Illinois | O17: United States | P17: Preliminary Diligence | Q17: Alaina Hartnett
A18: EV0017 | B18: Attune Neurosci | C18: 2 | D18: 46055 | E18: 46062 | F18: 2026-02-02; 2026-02-09 | G18: Deep Diligence | H18: 46062 | J18: Series A | K18: 20000000 | L18: Health | M18: San Francisco | N18: California | O18: United States | P18: Pass | Q18: Rachel Field
A19: EV0018 | B19: Cetos Water | C19: 2 | D19: 46168 | E19: 46174 | F19: 2026-05-26; 2026-06-01 | G19: Preliminary Diligence | J19: Seed | K19: 7000000 | L19: Climate | M19: New York | N19: New York | O19: United States | P19: Preliminary Diligence | Q19: Alaina Hartnett
A20: EV0019 | B20: CloverLeaf | C20: 2 | D20: 45999 | E20: 46006 | F20: 2025-12-08; 2025-12-15 | G20: Deep Diligence | H20: 46006 | J20: Seed | K20: 12000000 | L20: Health | M20: New Haven | N20: Connecticut | O20: United States | P20: Pass | Q20: Dan Resnicow
A21: EV0020 | B21: 1AU | C21: 1 | D21: 46118 | E21: 46118 | F21: 2026-04-06 | G21: Preliminary Diligence | L21: Systems
A22: EV0021 | B22: Blisk Dynamics | C22: 1 | D22: 46251 | E22: 46251 | F22: 2026-08-17 | G22: Preliminary Diligence | J22: Seed | K22: 10000000 | L22: Systems; Climate | P22: Pass | Q22: Rachel Field
A23: EV0022 | B23: Daedalus | C23: 1 | D23: 46195 | E23: 46195 | F23: 2026-06-22 | G23: Preliminary Diligence | J23: Series B | K23: 15000000 | L23: Systems | M23: San Francisco | N23: California | O23: United States | P23: Pass | Q23: Vinny Beranek
A24: EV0023 | B24: El Agente | C24: 1 | D24: 46055 | E24: 46055 | F24: 2026-02-02 | G24: Preliminary Diligence | J24: Seed | K24: 20000000 | L24: Systems | P24: Wait | Q24: Madeleine Laitz
A25: EV0024 | B25: ExploreTech | C25: 1 | D25: 46230 | E25: 46230 | F25: 2026-07-27 | G25: Preliminary Diligence | J25: Seed | K25: 8000000 | L25: Climate | M25: San Diego | N25: California | O25: United States | P25: Preliminary Diligence | Q25: Alaina Hartnett
A26: EV0025 | B26: Flume | C26: 1 | D26: 46111 | E26: 46111 | F26: 2026-03-30 | G26: Preliminary Diligence | J26: Series A | K26: 15000000 | L26: Systems | M26: New York | N26: New York | O26: United States | P26: Pass | Q26: Madeleine Laitz
